<?xml version="1.0" ?>
<!-- =================================================================================== -->
<!-- |    This document was autogenerated by xacro from /home/masaru/RoboCup2018RVRL_Playground/src/p3at_urdf/p3at_description/urdf/pioneer3at.urdf.xacro | -->
<!-- |    EDITING THIS FILE BY HAND IS NOT RECOMMENDED                                 | -->
<!-- =================================================================================== -->
<robot name="pioneer3at" xmlns:controller="http://playerstage.sourceforge.net/gazebo/xmlschema/#controller" xmlns:interface="http://playerstage.sourceforge.net/gazebo/xmlschema/#interface" xmlns:sensor="http://playerstage.sourceforge.net/gazebo/xmlschema/#sensor" xmlns:xacro="http://ros.org/wiki/xacro">
  <!-- Chassis -->
  <link name="base_link">
    <inertial>
      <mass value="14.0"/>
      <origin xyz="0 0 0.04"/>
      <inertia ixx="0.14711667" ixy="0.0" ixz="0.0" iyy="0.334951167" iyz="0.0" izz="0.3978345"/>
    </inertial>
    <visual name="base_visual">
      <origin rpy="0 0 0" xyz="0 0 0.18"/>
      <geometry name="pioneer_geom">
        <mesh filename="package://rc2018rvrl/meshes/pioneer3at_ros/chassis.dae"/>
      </geometry>
    </visual>
    <collision>
      <origin rpy="0 0 0" xyz="0 0 0.18"/>
      <geometry>
        <box size="0.501 0.3 0.19"/>
      </geometry>
    </collision>
  </link>
  <link name="p3at_front_left_wheel">
    <inertial>
      <mass value="1.5"/>
      <origin xyz="0 0 0"/>
      <inertia ixx="0.005240625" ixy="0" ixz="0" iyy="0.005240625" iyz="0" izz="0.009075"/>
    </inertial>
    <visual name="visual">
      <origin rpy="0 0 0" xyz="0 0 0"/>
      <geometry name="geom">
        <mesh filename="package://rc2018rvrl/meshes/pioneer3at_ros/wheel.dae"/>
      </geometry>
    </visual>
    <collision>
      <origin rpy="0 0 0" xyz="0 0 0"/>
      <geometry>
        <cylinder length="0.075" radius="0.110"/>
      </geometry>
    </collision>
  </link>
  <joint name="p3at_front_left_wheel_joint" type="continuous">
    <axis xyz="0 0 -1"/>
    <limit effort="100" velocity="100"/>
    <joint_properties damping="0.7"/>
    <origin rpy="1.5707 0 0" xyz="0.125 0.2010 0.11"/>
    <parent link="base_link"/>
    <child link="p3at_front_left_wheel"/>
  </joint>
  <link name="p3at_front_right_wheel">
    <inertial>
      <mass value="1.5"/>
      <origin xyz="0 0 0"/>
      <inertia ixx="0.005240625" ixy="0" ixz="0" iyy="0.005240625" iyz="0" izz="0.009075"/>
    </inertial>
    <visual name="visual">
      <origin rpy="0 0 0" xyz="0 0 0"/>
      <geometry name="geom">
        <mesh filename="package://rc2018rvrl/meshes/pioneer3at_ros/wheel.dae"/>
      </geometry>
    </visual>
    <collision>
      <origin rpy="0 0 0" xyz="0 0 0"/>
      <geometry>
        <cylinder length="0.075" radius="0.110"/>
      </geometry>
    </collision>
  </link>
  <joint name="p3at_front_right_wheel_joint" type="continuous">
    <axis xyz="0 0 -1"/>
    <limit effort="100" velocity="100"/>
    <joint_properties damping="0.7"/>
    <origin rpy="1.5707 0 0" xyz="0.125 -0.2010 0.11"/>
    <parent link="base_link"/>
    <child link="p3at_front_right_wheel"/>
  </joint>
  <link name="p3at_rear_left_wheel">
    <inertial>
      <mass value="1.5"/>
      <origin xyz="0 0 0"/>
      <inertia ixx="0.005240625" ixy="0" ixz="0" iyy="0.005240625" iyz="0" izz="0.009075"/>
    </inertial>
    <visual name="visual">
      <origin rpy="0 0 0" xyz="0 0 0"/>
      <geometry name="geom">
        <mesh filename="package://rc2018rvrl/meshes/pioneer3at_ros/wheel.dae"/>
      </geometry>
    </visual>
    <collision>
      <origin rpy="0 0 0" xyz="0 0 0"/>
      <geometry>
        <cylinder length="0.075" radius="0.110"/>
      </geometry>
    </collision>
  </link>
  <joint name="p3at_rear_left_wheel_joint" type="continuous">
    <axis xyz="0 0 -1"/>
    <limit effort="100" velocity="100"/>
    <joint_properties damping="0.7"/>
    <origin rpy="1.5707 0 0" xyz="-0.125 0.2010 0.11"/>
    <parent link="base_link"/>
    <child link="p3at_rear_left_wheel"/>
  </joint>
  <link name="p3at_rear_right_wheel">
    <inertial>
      <mass value="1.5"/>
      <origin xyz="0 0 0"/>
      <inertia ixx="0.005240625" ixy="0" ixz="0" iyy="0.005240625" iyz="0" izz="0.009075"/>
    </inertial>
    <visual name="visual">
      <origin rpy="0 0 0" xyz="0 0 0"/>
      <geometry name="geom">
        <mesh filename="package://rc2018rvrl/meshes/pioneer3at_ros/wheel.dae"/>
      </geometry>
    </visual>
    <collision>
      <origin rpy="0 0 0" xyz="0 0 0"/>
      <geometry>
        <cylinder length="0.075" radius="0.110"/>
      </geometry>
    </collision>
  </link>
  <joint name="p3at_rear_right_wheel_joint" type="continuous">
    <axis xyz="0 0 -1"/>
    <limit effort="100" velocity="100"/>
    <joint_properties damping="0.7"/>
    <origin rpy="1.5707 0 0" xyz="-0.125 -0.2010 0.11"/>
    <parent link="base_link"/>
    <child link="p3at_rear_right_wheel"/>
  </joint>
  <gazebo>
    <plugin filename="libgazebo_ros_skid_steer_drive.so" name="skid_steer_drive_controller">
      <updateRate>100.0</updateRate>
      <!--robotNamespace>$(arg robot_name)</robotNamespace-->
      <leftFrontJoint>p3at_front_left_wheel_joint</leftFrontJoint>
      <rightFrontJoint>p3at_front_right_wheel_joint</rightFrontJoint>
      <leftRearJoint>p3at_rear_left_wheel_joint</leftRearJoint>
      <rightRearJoint>p3at_rear_right_wheel_joint</rightRearJoint>
      <wheelSeparation>0.4</wheelSeparation>
      <wheelDiameter>0.215</wheelDiameter>
      <robotBaseFrame>base_link</robotBaseFrame>
      <torque>200</torque>
      <commandTopic>cmd_vel</commandTopic>
      <odometryTopic>odom</odometryTopic>
      <odometryFrame>odom</odometryFrame>
      <broadcastTF>true</broadcastTF>
    </plugin>
  </gazebo>
  <!--xacro:include filename="$(find p3at_description)/urdf/velodyne.urdf.xacro"/>
<xacro:rotating_velodyne name="hokuyo" parent="base_link" ros_topic="hokuyo" update_rate="25" ray_count="360" min_angle="160" max_angle="-160" >
    <origin xyz="0.13 0 0.32" rpy="0 0 0"/>
  </xacro:rotating_velodyne-->
  <joint name="hokuyo_joint" type="fixed">
    <origin rpy="0 0 0" xyz="0.13 0 0.32"/>
    <parent link="base_link"/>
    <child link="hokuyo_frame"/>
  </joint>
  <link name="hokuyo_frame">
    <inertial>
      <mass value="0.270"/>
      <origin rpy="0 0 0" xyz="0 0 0"/>
      <inertia ixx="2.632e-4" ixy="0" ixz="0" iyy="2.632e-4" iyz="0" izz="1.62e-4"/>
    </inertial>
    <visual>
      <origin rpy="0 0 0" xyz="0 0 0"/>
      <geometry>
        <mesh filename="package://rc2018rvrl/meshes/pioneer3at_ros/hokuyo_utm_30lx.dae"/>
      </geometry>
    </visual>
    <collision>
      <origin rpy="0 0 0" xyz="0 0 -0.0115"/>
      <geometry>
        <box size="0.058 0.058 0.087"/>
      </geometry>
    </collision>
  </link>
  <gazebo reference="hokuyo_frame">
    <sensor name="hokuyo" type="ray">
      <always_on>true</always_on>
      <update_rate>30</update_rate>
      <pose>0 0 0 0 0 0</pose>
      <visualize>false</visualize>
      <ray>
        <scan>
          <horizontal>
            <samples>1040</samples>
            <resolution>1</resolution>
            <min_angle>2.26892802759</min_angle>
            <max_angle>-2.26892802759</max_angle>
          </horizontal>
        </scan>
        <range>
          <min>0.08</min>
          <max>30.0</max>
          <resolution>0.01</resolution>
        </range>
      </ray>
      <plugin filename="libgazebo_ros_laser.so" name="gazebo_ros_hokuyo_controller">
        <gaussianNoise>0.005</gaussianNoise>
        <alwaysOn>true</alwaysOn>
        <updateRate>30</updateRate>
        <topicName>hokuyo</topicName>
        <frameName>hokuyo_frame</frameName>
      </plugin>
    </sensor>
  </gazebo>
  <joint name="camera_joint" type="fixed">
    <origin rpy="0 0 0" xyz="0.095 0.0 0.38"/>
    <parent link="base_link"/>
    <child link="camera_link"/>
  </joint>
  <link name="camera_link">
    <inertial>
      <mass value="0.200"/>
      <origin rpy="0 0 0" xyz="0 0 0"/>
      <inertia ixx="5.8083e-4" ixy="0" ixz="0" iyy="3.0833e-5" iyz="0" izz="5.9083e-4"/>
    </inertial>
    <visual>
      <origin rpy="0 0 0" xyz="0 0 0"/>
      <geometry>
        <mesh filename="rc2018rvrl/meshes/pioneer3at_ros/asus_camera_simple.dae"/>
      </geometry>
    </visual>
    <!--
       <collision>
          <origin xyz="0 0 0" rpy="0 0 0" />
          <geometry>
            <box size="0.035 0.185 0.025"/>
          </geometry>
        </collision>
        -->
    <collision>
      <origin rpy="0 0 0" xyz="0 0 0"/>
      <geometry>
        <mesh filename="package://rc2018rvrl/meshes/pioneer3at_ros/asus_camera_simple.dae"/>
      </geometry>
    </collision>
  </link>
  <joint name="camera_depth_joint" type="fixed">
    <origin rpy="0 0 0" xyz="0.0 0.049 0.0"/>
    <parent link="camera_link"/>
    <child link="camera_depth_frame"/>
  </joint>
  <link name="camera_depth_frame"/>
  <joint name="camera_depth_optical_joint" type="fixed">
    <origin rpy="-1.57079632679 0.0 -1.57079632679" xyz="0 0 0"/>
    <parent link="camera_depth_frame"/>
    <child link="camera_depth_optical_frame"/>
  </joint>
  <link name="camera_depth_optical_frame"/>
  <joint name="camera_rgb_joint" type="fixed">
    <origin rpy="0 0 0" xyz="0.0 0.022 0.0"/>
    <parent link="camera_link"/>
    <child link="camera_rgb_frame"/>
  </joint>
  <link name="camera_rgb_frame"/>
  <joint name="camera_rgb_optical_joint" type="fixed">
    <origin rpy="-1.57079632679 0.0 -1.57079632679" xyz="0 0 0"/>
    <parent link="camera_rgb_frame"/>
    <child link="camera_rgb_optical_frame"/>
  </joint>
  <link name="camera_rgb_optical_frame"/>
  <!-- ASUS Xtion PRO camera for simulation -->
  <gazebo reference="camera_depth_frame">
    <sensor name="camera" type="depth">
      <update_rate>30</update_rate>
      <camera>
        <horizontal_fov>1.09606677025</horizontal_fov>
        <image>
          <format>R8G8B8</format>
          <width>320</width>
          <!--640-->
          <height>240</height>
          <!--480-->
        </image>
        <clip>
          <near>0.5</near>
          <far>19</far>
        </clip>
      </camera>
      <plugin filename="libgazebo_ros_openni_kinect.so" name="camera_camera_controller">
        <imageTopicName>camera/rgb/image_raw</imageTopicName>
        <cameraInfoTopicName>camera/rgb/camera_info</cameraInfoTopicName>
        <depthImageTopicName>camera/depth/image_raw</depthImageTopicName>
        <depthImageCameraInfoTopicName>camera/depth/camera_info</depthImageCameraInfoTopicName>
        <pointCloudTopicName>camera/depth/points</pointCloudTopicName>
        <frameName>camera_depth_optical_frame</frameName>
      </plugin>
    </sensor>
  </gazebo>
  <joint name="thermal_joint" type="fixed">
    <origin rpy="0 0 0" xyz="0.105 0.0 0.41"/>
    <parent link="base_link"/>
    <child link="thermal_frame"/>
  </joint>
  <link name="thermal_frame">
    <inertial>
      <mass value="0.200"/>
      <origin rpy="0 0 0" xyz="0 0 0"/>
      <inertia ixx="5.8083e-4" ixy="0" ixz="0" iyy="3.0833e-5" iyz="0" izz="5.9083e-4"/>
    </inertial>
    <visual>
      <origin rpy="0 0 0" xyz="-0.053 0 0"/>
      <geometry>
        <!--Dimensions taken from http://www.flir.com/automation/display/?id=56341-->
        <box size="0.106 0.04 0.043"/>
      </geometry>
      <material name="DarkGrey">
        <color rgba="0.3 0.3 0.3 1"/>
      </material>
    </visual>
    <collision>
      <origin rpy="0 0 0" xyz="-0.053 0 0"/>
      <geometry>
        <!--Dimensions taken from http://www.flir.com/automation/display/?id=56341-->
        <box size="0.106 0.04 0.043"/>
      </geometry>
    </collision>
  </link>
  <joint name="thermal_optical_joint" type="fixed">
    <origin rpy="-1.57079632679 0.0 -1.57079632679" xyz="0 0 0"/>
    <parent link="thermal_frame"/>
    <child link="thermal_optical_frame"/>
  </joint>
  <link name="thermal_optical_frame"/>
  <gazebo reference="thermal_frame">
    <material>Gazebo/Grey</material>
  </gazebo>
  <gazebo reference="thermal_frame">
    <sensor name="thermal_camera_sensor" type="camera">
      <update_rate>10</update_rate>
      <camera>
        <horizontal_fov>1.09606677025</horizontal_fov>
        <image>
          <format>R8G8B8</format>
          <width>160</width>
          <!--640-->
          <height>120</height>
          <!--480-->
        </image>
        <clip>
          <near>0.5</near>
          <far>19</far>
        </clip>
      </camera>
<!--
      <plugin filename="package://p3at_urdf/libgazebo_ros_thermal_camera_pink.so" name="thermal_camera_controller">
        <alwaysOn>true</alwaysOn>
        <updateRate>10</updateRate>
        <imageTopicName>thermal/image</imageTopicName>
        <cameraInfoTopicName>thermal/camera_info</cameraInfoTopicName>
        <frameName>thermal_optical_frame</frameName>
      </plugin>
-->
    </sensor>
  </gazebo>
</robot>

