<?xml version="1.0" ?>
<!-- =================================================================================== -->
<!-- |    This document was autogenerated by xacro from /home/masaru/RoboCup2018RVRL_Playground/src/p3at_description/urdf/pioneer3at.urdf.xacro | -->
<!-- |    EDITING THIS FILE BY HAND IS NOT RECOMMENDED                                 | -->
<!-- =================================================================================== -->
<robot name="pioneer3at" xmlns:controller="http://playerstage.sourceforge.net/gazebo/xmlschema/#controller" xmlns:interface="http://playerstage.sourceforge.net/gazebo/xmlschema/#interface" xmlns:sensor="http://playerstage.sourceforge.net/gazebo/xmlschema/#sensor" xmlns:xacro="http://ros.org/wiki/xacro">
  <!-- Chassis -->
  <link name="base_link">
    <inertial>
      <mass value="14.0"/>
      <origin xyz="0 0 0.177"/>
      <inertia ixx="0.14711667" ixy="0.0" ixz="0.0" iyy="0.334951167" iyz="0.0" izz="0.3978345"/>
    </inertial>
    <visual name="base_visual">
      <origin rpy="0 0 0" xyz="0 0 0.18"/>
      <geometry name="pioneer_geom">
        <mesh filename="package://p3at_description/meshes/p3at_meshes/chassis.dae"/>
      </geometry>
    </visual>
    <collision>
      <origin rpy="0 0 0" xyz="0 0 0.18"/>
      <geometry>
        <box size="0.501 0.3 0.19"/>
      </geometry>
    </collision>
  </link>
  <link name="p3at_front_left_wheel">
    <inertial>
      <mass value="1.5"/>
      <origin xyz="0 0 0"/>
      <inertia ixx="0.005240625" ixy="0" ixz="0" iyy="0.005240625" iyz="0" izz="0.009075"/>
    </inertial>
    <visual name="visual">
      <origin rpy="0 0 0" xyz="0 0 0"/>
      <geometry name="geom">
        <mesh filename="package://p3at_description/meshes/p3at_meshes/wheel.dae"/>
      </geometry>
    </visual>
    <collision>
      <origin rpy="0 0 0" xyz="0 0 0"/>
      <geometry>
        <cylinder length="0.075" radius="0.110"/>
      </geometry>
    </collision>
  </link>
  <joint name="p3at_front_left_wheel_joint" type="continuous">
    <axis xyz="0 0 -1"/>
    <limit effort="100" velocity="100"/>
    <joint_properties damping="0.7"/>
    <origin rpy="1.5707 0 0" xyz="0.125 0.2010 0.11"/>
    <parent link="base_link"/>
    <child link="p3at_front_left_wheel"/>
  </joint>
  <link name="p3at_front_right_wheel">
    <inertial>
      <mass value="1.5"/>
      <origin xyz="0 0 0"/>
      <inertia ixx="0.005240625" ixy="0" ixz="0" iyy="0.005240625" iyz="0" izz="0.009075"/>
    </inertial>
    <visual name="visual">
      <origin rpy="0 0 0" xyz="0 0 0"/>
      <geometry name="geom">
        <mesh filename="package://p3at_description/meshes/p3at_meshes/wheel.dae"/>
      </geometry>
    </visual>
    <collision>
      <origin rpy="0 0 0" xyz="0 0 0"/>
      <geometry>
        <cylinder length="0.075" radius="0.110"/>
      </geometry>
    </collision>
  </link>
  <joint name="p3at_front_right_wheel_joint" type="continuous">
    <axis xyz="0 0 -1"/>
    <limit effort="100" velocity="100"/>
    <joint_properties damping="0.7"/>
    <origin rpy="1.5707 0 0" xyz="0.125 -0.2010 0.11"/>
    <parent link="base_link"/>
    <child link="p3at_front_right_wheel"/>
  </joint>
  <link name="p3at_rear_left_wheel">
    <inertial>
      <mass value="1.5"/>
      <origin xyz="0 0 0"/>
      <inertia ixx="0.005240625" ixy="0" ixz="0" iyy="0.005240625" iyz="0" izz="0.009075"/>
    </inertial>
    <visual name="visual">
      <origin rpy="0 0 0" xyz="0 0 0"/>
      <geometry name="geom">
        <mesh filename="package://p3at_description/meshes/p3at_meshes/wheel.dae"/>
      </geometry>
    </visual>
    <collision>
      <origin rpy="0 0 0" xyz="0 0 0"/>
      <geometry>
        <cylinder length="0.075" radius="0.110"/>
      </geometry>
    </collision>
  </link>
  <joint name="p3at_rear_left_wheel_joint" type="continuous">
    <axis xyz="0 0 -1"/>
    <limit effort="100" velocity="100"/>
    <joint_properties damping="0.7"/>
    <origin rpy="1.5707 0 0" xyz="-0.125 0.2010 0.11"/>
    <parent link="base_link"/>
    <child link="p3at_rear_left_wheel"/>
  </joint>
  <link name="p3at_rear_right_wheel">
    <inertial>
      <mass value="1.5"/>
      <origin xyz="0 0 0"/>
      <inertia ixx="0.005240625" ixy="0" ixz="0" iyy="0.005240625" iyz="0" izz="0.009075"/>
    </inertial>
    <visual name="visual">
      <origin rpy="0 0 0" xyz="0 0 0"/>
      <geometry name="geom">
        <mesh filename="package://p3at_description/meshes/p3at_meshes/wheel.dae"/>
      </geometry>
    </visual>
    <collision>
      <origin rpy="0 0 0" xyz="0 0 0"/>
      <geometry>
        <cylinder length="0.075" radius="0.110"/>
      </geometry>
    </collision>
  </link>
  <joint name="p3at_rear_right_wheel_joint" type="continuous">
    <axis xyz="0 0 -1"/>
    <limit effort="100" velocity="100"/>
    <joint_properties damping="0.7"/>
    <origin rpy="1.5707 0 0" xyz="-0.125 -0.2010 0.11"/>
    <parent link="base_link"/>
    <child link="p3at_rear_right_wheel"/>
  </joint>
  <gazebo>
    <plugin filename="libgazebo_ros_skid_steer_drive.so" name="skid_steer_drive_controller">
      <updateRate>100.0</updateRate>
      <robotNamespace>robot</robotNamespace>
      <leftFrontJoint>p3at_front_left_wheel_joint</leftFrontJoint>
      <rightFrontJoint>p3at_front_right_wheel_joint</rightFrontJoint>
      <leftRearJoint>p3at_rear_left_wheel_joint</leftRearJoint>
      <rightRearJoint>p3at_rear_right_wheel_joint</rightRearJoint>
      <wheelSeparation>0.4</wheelSeparation>
      <wheelDiameter>0.215</wheelDiameter>
      <robotBaseFrame>base_link</robotBaseFrame>
      <torque>200</torque>
      <commandTopic>cmd_vel</commandTopic>
      <odometryTopic>odom</odometryTopic>
      <odometryFrame>odom</odometryFrame>
      <broadcastTF>true</broadcastTF>
    </plugin>
  </gazebo>
  <joint name="hokuyo_joint" type="fixed">
    <origin rpy="0 0 0" xyz="0.13 0 0.32"/>
    <parent link="base_link"/>
    <child link="hokuyo_link"/>
  </joint>
  <link name="hokuyo_link">
    <inertial>
      <mass value="0.270"/>
      <origin rpy="0 0 0" xyz="0 0 0"/>
      <inertia ixx="2.632e-4" ixy="0" ixz="0" iyy="2.632e-4" iyz="0" izz="1.62e-4"/>
    </inertial>
    <visual>
      <origin rpy="0 0 0" xyz="0 0 0"/>
      <geometry>
        <mesh filename="package://p3at_description/meshes/hokuyo_utm30lx/hokuyo_utm_30lx.dae"/>
      </geometry>
    </visual>
    <collision>
      <origin rpy="0 0 0" xyz="0 0 -0.0115"/>
      <geometry>
        <box size="0.058 0.058 0.087"/>
      </geometry>
    </collision>
  </link>
  <gazebo reference="hokuyo_link">
    <sensor name="hokuyo" type="ray">
      <always_on>true</always_on>
      <update_rate>30</update_rate>
      <pose>0 0 0 0 0 0</pose>
      <visualize>false</visualize>
      <ray>
        <scan>
          <horizontal>
            <samples>1040</samples>
            <resolution>1</resolution>
            <min_angle>-3*M_PI/4</min_angle>
            <max_angle>3*M_PI/4</max_angle>
          </horizontal>
        </scan>
        <range>
          <min>0.08</min>
          <max>30.0</max>
          <resolution>0.01</resolution>
        </range>
      </ray>
      <plugin filename="libgazebo_ros_laser.so" name="gazebo_ros_hokuyo_controller">
        <gaussianNoise>0.005</gaussianNoise>
        <alwaysOn>true</alwaysOn>
        <updateRate>30</updateRate>
        <topicName>hokuyo</topicName>
        <frameName>hokuyo_link</frameName>
      </plugin>
    </sensor>
  </gazebo>
</robot>

